<?xml version="1.0" ?>
<!-- =================================================================================== -->
<!-- |    This document was autogenerated by xacro from src/bimanualrobot_ros2/bimanualrobot_description/urdf/robots/bimanualrobot.urdf.xacro | -->
<!-- |    EDITING THIS FILE BY HAND IS NOT RECOMMENDED                                 | -->
<!-- =================================================================================== -->
<!-- Revolute-Revolute Manipulator -->
<robot name="bimanualrobot">
  <material name="black">
    <color rgba="0.0 0.0 0.0 1.0"/>
  </material>
  <material name="blue">
    <color rgba="0.0 0.0 0.8 1.0"/>
  </material>
  <material name="green">
    <color rgba="0.0 0.8 0.0 1.0"/>
  </material>
  <material name="grey">
    <color rgba="0.2 0.2 0.2 1.0"/>
  </material>
  <material name="light_grey">
    <color rgba="0.7 0.7 0.7 1.0"/>
  </material>
  <material name="orange">
    <color rgba="1.0 0.4235294117647059 0.0392156862745098 1.0"/>
  </material>
  <material name="brown">
    <color rgba="0.8705882352941177 0.8117647058823529 0.7647058823529411 1.0"/>
  </material>
  <material name="red">
    <color rgba="0.8 0.0 0.0 1.0"/>
  </material>
  <material name="white">
    <color rgba="1.0 1.0 1.0 1.0"/>
  </material>
  <material name="wood">
    <color rgba="0.8705882352941177 0.8117647058823529 0.7647058823529411 1.0"/>
  </material>
  <link name="base_link"/>
  <joint name="base_link__base_joint" type="fixed">
    <origin rpy="0 0 0" xyz="0 0 0"/>
    <parent link="base_link"/>
    <child link="stand_link"/>
  </joint>
  <link name="stand_link">
    <visual>
      <origin rpy="1.5707963267948966 0 0" xyz="0 0 0"/>
      <geometry>
        <mesh filename="file:///home/thibaut/Documents/Bimanual_Robot/bimanual_ws/install/bimanualrobot_description/share/bimanualrobot_description/meshes/visual/stand.stl"/>
        <!-- <mesh filename="package://bbbot_description/meshes/visual/stand_low.stl" /> -->
      </geometry>
      <material name="light_grey"/>
    </visual>
    <collision>
      <origin rpy="0 0 0" xyz="-0.3 -0.3 0"/>
      <geometry>
        <mesh filename="file:///home/thibaut/Documents/Bimanual_Robot/bimanual_ws/install/bimanualrobot_description/share/bimanualrobot_description/meshes/collision/stand.stl"/>
      </geometry>
    </collision>
    <inertial>
      <origin rpy="0 0 0" xyz="0 0 0"/>
      <mass value="1000"/>
      <inertia ixx="100.0" ixy="0.0" ixz="0.0" iyy="100.0" iyz="0.0" izz="100.0"/>
    </inertial>
  </link>
  <!-- <xacro:include filename="$(find bimanualrobot_description)/urdf/control/common.xacro" /> -->
  <!-- <xacro:manipulator_arm_gazebo prefix="leftarm" />
  <xacro:manipulator_arm_gazebo prefix="rightarm" /> -->
  <!-- One of the values should be 226 mm -->
  <!-- Left arm -->
  <link name="left_base"/>
  <joint name="stand_to_left_base" type="fixed">
    <parent link="stand_link"/>
    <child link="left_base"/>
    <origin rpy="0 0 0" xyz="0 0 0"/>
  </joint>
  <!-- First element of the arm fixed to the parent -->
  <joint name="left_base_leftarm__base_joint" type="fixed">
    <origin rpy="-1.5707963267948966 -1.5707963267948966 0" xyz="0.045 0.1665 1.526"/>
    <parent link="left_base"/>
    <child link="leftarm_shoulder_link"/>
  </joint>
  <!-- link 1 -->
  <link name="leftarm_shoulder_link">
    <collision>
      <origin rpy="0 0 3.141592653589793" xyz="0 0 0.063"/>
      <geometry>
        <box size="0.054 0.054 0.126"/>
      </geometry>
    </collision>
    <visual>
      <origin rpy="0 0 3.141592653589793" xyz="0 0 0"/>
      <geometry>
        <mesh filename="file:///home/thibaut/Documents/Bimanual_Robot/bimanual_ws/install/bimanualrobot_description/share/bimanualrobot_description/meshes/visual/link_1.stl" scale="0.001 0.001 0.001"/>
      </geometry>
      <material name="grey"/>
    </visual>
    <inertial>
      <!-- <origin xyz="0 0 0" rpy="0 0 0"/> -->
      <!-- <mass value="0.936"/> -->
      <!-- <inertia ixx="1.0" ixy="0.0" ixz="0.0" iyy="1.0" iyz="0.0" izz="1.0" /> -->
      <origin rpy="0 0 0" xyz="0.00023 0.00000 0.06223"/>
      <mass value="0.85644"/>
      <!-- <inertia ixx="0.00121064" ixy="0.0" ixz="0.00001100" iyy="0.00120886" iyz="0.0" izz="0.00038103" /> -->
      <inertia ixx="0.00134118504" ixy="0.0" ixz="0.0" iyy="0.00134118504" iyz="0.0" izz="0.00041622984"/>
    </inertial>
  </link>
  <!-- Joint 1 -->
  <joint name="leftarm_shoulder_pan_joint" type="revolute">
    <parent link="leftarm_shoulder_link"/>
    <child link="leftarm_upper_arm_link"/>
    <origin rpy="0 0 0" xyz="0 0 0.126"/>
    <axis xyz="0 0 -1"/>
    <limit effort="1000" lower="-3.141592653589793" upper="0" velocity="15"/>
    <dynamics damping="0"/>
  </joint>
  <!-- link 2 -->
  <link name="leftarm_upper_arm_link">
    <collision>
      <origin rpy="0 0 3.141592653589793" xyz="0 0 0.03"/>
      <geometry>
        <box size="0.06 0.14 0.06"/>
      </geometry>
    </collision>
    <visual>
      <origin rpy="0 0 3.141592653589793" xyz="0 0 -0.126"/>
      <geometry>
        <mesh filename="file:///home/thibaut/Documents/Bimanual_Robot/bimanual_ws/install/bimanualrobot_description/share/bimanualrobot_description/meshes/visual/link_2.stl" scale="0.001 0.001 0.001"/>
      </geometry>
      <material name="grey"/>
    </visual>
    <inertial>
      <!-- <origin xyz="0 0 0" rpy="0 0 0"/> -->
      <!-- <mass value="1.030"/> -->
      <!-- <inertia ixx="1.0" ixy="0.0" ixz="0.0" iyy="1.0" iyz="0.0" izz="1.0" /> -->
      <origin rpy="0 0 0" xyz="0.00000 0.00080 0.03183"/>
      <mass value="0.94658"/>
      <!-- <inertia ixx="0.00152547" ixy="0.0" ixz="0.0" iyy="0.00045954" iyz="-0.00001086" izz="0.00151740" /> -->
      <inertia ixx="0.00183005466667" ixy="0.0" ixz="0.0" iyy="0.000567948" iyz="0.0" izz="0.00183005466667"/>
    </inertial>
  </link>
  <!-- Joint 2 -->
  <joint name="leftarm_shoulder_lift_joint" type="revolute">
    <parent link="leftarm_upper_arm_link"/>
    <child link="leftarm_forearm_link"/>
    <origin rpy="0 0 0" xyz="0 0 0.033"/>
    <axis xyz="0 1 0"/>
    <limit effort="1000" lower="-1.7803405567893358" upper="1.7803405567893358" velocity="15"/>
    <dynamics damping="0"/>
  </joint>
  <!-- link 3 -->
  <link name="leftarm_forearm_link">
    <collision>
      <origin rpy="1.5707963267948966 0 3.141592653589793" xyz="-.001 0 0.148"/>
      <geometry>
        <mesh filename="file:///home/thibaut/Documents/Bimanual_Robot/bimanual_ws/install/bimanualrobot_description/share/bimanualrobot_description/meshes/collision/link3.stl"/>
      </geometry>
    </collision>
    <visual>
      <origin rpy="0 0 3.141592653589793" xyz="0 0 -0.159"/>
      <geometry>
        <mesh filename="file:///home/thibaut/Documents/Bimanual_Robot/bimanual_ws/install/bimanualrobot_description/share/bimanualrobot_description/meshes/visual/link_3.stl" scale="0.001 0.001 0.001"/>
      </geometry>
      <material name="grey"/>
    </visual>
    <inertial>
      <origin rpy="0 0 0" xyz="0 0 0.148"/>
      <!-- <mass value="1.404"/> -->
      <!-- <inertia ixx="1.0" ixy="0.0" ixz="0.0" iyy="1.0" iyz="0.0" izz="1.0" /> -->
      <mass value="1.30260"/>
      <!-- <inertia ixx="0.01111021" ixy="0.00001331" ixz="-0.00134208" iyy="0.01046642" iyz="0.00016235" izz="0.00202081" /> -->
      <inertia ixx="0.0136625102365" ixy="0.0" ixz="0.0" iyy="0.0124082569044" iyz="0.0" izz="0.00324753226791"/>
    </inertial>
  </link>
  <!-- Joint 3 -->
  <joint name="leftarm_elbow_joint" type="revolute">
    <parent link="leftarm_forearm_link"/>
    <child link="leftarm_wrist_1_link"/>
    <origin rpy="0 0.7853981633974483 0" xyz="0.03 0.0 0.264"/>
    <axis xyz="0 1 0"/>
    <limit effort="1000" lower="-1.2566370614359172" upper="2.261946710584651" velocity="15"/>
    <dynamics damping="0"/>
  </joint>
  <!-- link 4 -->
  <link name="leftarm_wrist_1_link">
    <collision>
      <origin rpy="1.5707963267948966 0 3.141592653589793" xyz="-0.03 0.0 0.1285"/>
      <geometry>
        <mesh filename="file:///home/thibaut/Documents/Bimanual_Robot/bimanual_ws/install/bimanualrobot_description/share/bimanualrobot_description/meshes/collision/link4.stl"/>
      </geometry>
    </collision>
    <visual>
      <origin rpy="0 0 3.141592653589793" xyz="-0.03 0 -0.423"/>
      <geometry>
        <mesh filename="file:///home/thibaut/Documents/Bimanual_Robot/bimanual_ws/install/bimanualrobot_description/share/bimanualrobot_description/meshes/visual/link_4.stl" scale="0.001 0.001 0.001"/>
      </geometry>
      <material name="grey"/>
    </visual>
    <inertial>
      <origin rpy="0 1.5707963267948966 0" xyz="-0.03 0 0.1285"/>
      <!-- <mass value="1.236" /> -->
      <!-- <inertia ixx="1.0" ixy="0.0" ixz="0.0" iyy="1.0" iyz="0.0" izz="1.0" /> -->
      <mass value="1.15977"/>
      <!-- <inertia ixx="0.00096726" ixy="0.00004383" ixz="-0.00002771" iyy="0.00318801" iyz="0.00000627" izz="0.00341484" /> -->
      <inertia ixx="0.00205032491251" ixy="0.0" ixz="0.0" iyy="0.00691847164616" iyz="0.0" izz="0.00765159473365"/>
    </inertial>
  </link>
  <!-- Joint 4 -->
  <joint name="leftarm_wrist_1_joint" type="revolute">
    <parent link="leftarm_wrist_1_link"/>
    <child link="leftarm_wrist_2_link"/>
    <origin rpy="0 0 0" xyz="-0.03 0.0 0.231"/>
    <axis xyz="0 0 1"/>
    <limit effort="1000" lower="-3.141592653589793" upper="3.141592653589793" velocity="15"/>
    <dynamics damping="0"/>
  </joint>
  <!-- link 5 -->
  <link name="leftarm_wrist_2_link">
    <collision>
      <origin rpy="0 0 3.141592653589793" xyz="0.0 0.0 0.024"/>
      <geometry>
        <box size="0.048 0.09 0.048"/>
      </geometry>
    </collision>
    <visual>
      <origin rpy="0 0 3.141592653589793" xyz="0 0 -0.654"/>
      <geometry>
        <mesh filename="file:///home/thibaut/Documents/Bimanual_Robot/bimanual_ws/install/bimanualrobot_description/share/bimanualrobot_description/meshes/visual/link_5.stl" scale="0.001 0.001 0.001"/>
      </geometry>
      <material name="grey"/>
    </visual>
    <inertial>
      <origin rpy="0 0 0" xyz="0 0 0.024"/>
      <!-- <mass value="0.491" /> -->
      <!-- <inertia ixx="1.0" ixy="0.0" ixz="0.0" iyy="1.0" iyz="0.0" izz="1.0" /> -->
      <mass value="0.44688"/>
      <!-- <inertia ixx="0.00030285" ixy="0.00000761" ixz="0.00000031" iyy="0.00022339" iyz="-0.00000001" izz="0.00039766" /> -->
      <inertia ixx="0.00038744496" ixy="0.0" ixz="0.0" iyy="0.00017160192" iyz="0.0" izz="0.00038744496"/>
    </inertial>
  </link>
  <!-- Joint 5 -->
  <joint name="leftarm_wrist_2_joint" type="revolute">
    <parent link="leftarm_wrist_2_link"/>
    <child link="leftarm_wrist_3_link"/>
    <origin rpy="0 0 0" xyz="0.0 0.0 0.027"/>
    <axis xyz="0 1 0"/>
    <limit effort="1000" lower="-1.5707963267948966" upper="1.5707963267948966" velocity="15"/>
    <dynamics damping="0"/>
  </joint>
  <!-- link 6 -->
  <link name="leftarm_wrist_3_link">
    <collision>
      <origin rpy="1.5707963267948966 0 1.5707963267948966" xyz="0.0 0.0 0.081"/>
      <geometry>
        <mesh filename="file:///home/thibaut/Documents/Bimanual_Robot/bimanual_ws/install/bimanualrobot_description/share/bimanualrobot_description/meshes/collision/link6.stl"/>
      </geometry>
    </collision>
    <visual>
      <origin rpy="0 0 3.141592653589793" xyz="0 0 -0.681"/>
      <geometry>
        <mesh filename="file:///home/thibaut/Documents/Bimanual_Robot/bimanual_ws/install/bimanualrobot_description/share/bimanualrobot_description/meshes/visual/link_6.stl" scale="0.001 0.001 0.001"/>
      </geometry>
      <material name="grey"/>
    </visual>
    <inertial>
      <origin rpy="1.5707963267948966 1.5707963267948966 0" xyz="0 0 0.081"/>
      <!-- <mass value="0.454" /> -->
      <!-- <inertia ixx="1.0" ixy="0.0" ixz="0.0" iyy="1.0" iyz="0.0" izz="1.0" /> -->
      <mass value="0.43273"/>
      <!-- <inertia ixx="0.00021512" ixy="0.00001009" ixz="0.00000000" iyy="0.00042827" iyz="0.00000000" izz="0.00051436" /> -->
      <inertia ixx="0.00039594795" ixy="0.0" ixz="0.0" iyy="0.00104401581334" iyz="0.0" izz="0.000775290483338"/>
    </inertial>
  </link>
  <!-- Joint 6 -->
  <joint name="leftarm_wrist_3_joint" type="revolute">
    <parent link="leftarm_wrist_3_link"/>
    <child link="leftarm_ee_link"/>
    <origin rpy="0 0 0" xyz="0.0 0.0 0.123"/>
    <axis xyz="0 0 1"/>
    <limit effort="1000" lower="-3.141592653589793" upper="3.141592653589793" velocity="15"/>
    <dynamics damping="0"/>
  </joint>
  <!-- End Effector -->
  <link name="leftarm_ee_link">
    <collision>
      <origin rpy="0 0 0" xyz="0.0 0.0 0.0"/>
      <geometry>
        <box size="0.0 0.0 0.0"/>
      </geometry>
    </collision>
    <visual>
      <origin rpy="0 0 0" xyz="0.0 0.0 0.0"/>
      <geometry>
        <box size="0.0 0.0 0.0"/>
      </geometry>
      <material name="red"/>
    </visual>
    <inertial>
      <origin rpy="0 0 0" xyz="0 0 0"/>
      <mass value="0.01"/>
      <inertia ixx="0.0000416666666667" ixy="0.0" ixz="0.0" iyy="0.0000416666666667" iyz="0.0" izz="0.0000416666666667"/>
    </inertial>
  </link>
  <!-- <xacro:manipulator_arm_transmission prefix="${prefix_val}" /> -->
  <!-- Right arm -->
  <link name="right_base"/>
  <joint name="stand_to_right_base" type="fixed">
    <parent link="stand_link"/>
    <child link="right_base"/>
    <origin rpy="0 0 0" xyz="0 0 0"/>
  </joint>
  <!-- First element of the arm fixed to the parent -->
  <joint name="right_base_rightarm__base_joint" type="fixed">
    <origin rpy="1.5707963267948966 -1.5707963267948966 0" xyz="0.045 -0.1665 1.526"/>
    <parent link="right_base"/>
    <child link="rightarm_shoulder_link"/>
  </joint>
  <!-- link 1 -->
  <link name="rightarm_shoulder_link">
    <collision>
      <origin rpy="0 0 3.141592653589793" xyz="0 0 0.063"/>
      <geometry>
        <box size="0.054 0.054 0.126"/>
      </geometry>
    </collision>
    <visual>
      <origin rpy="0 0 3.141592653589793" xyz="0 0 0"/>
      <geometry>
        <mesh filename="file:///home/thibaut/Documents/Bimanual_Robot/bimanual_ws/install/bimanualrobot_description/share/bimanualrobot_description/meshes/visual/link_1.stl" scale="0.001 0.001 0.001"/>
      </geometry>
      <material name="grey"/>
    </visual>
    <inertial>
      <!-- <origin xyz="0 0 0" rpy="0 0 0"/> -->
      <!-- <mass value="0.936"/> -->
      <!-- <inertia ixx="1.0" ixy="0.0" ixz="0.0" iyy="1.0" iyz="0.0" izz="1.0" /> -->
      <origin rpy="0 0 0" xyz="0.00023 0.00000 0.06223"/>
      <mass value="0.85644"/>
      <!-- <inertia ixx="0.00121064" ixy="0.0" ixz="0.00001100" iyy="0.00120886" iyz="0.0" izz="0.00038103" /> -->
      <inertia ixx="0.00134118504" ixy="0.0" ixz="0.0" iyy="0.00134118504" iyz="0.0" izz="0.00041622984"/>
    </inertial>
  </link>
  <!-- Joint 1 -->
  <joint name="rightarm_shoulder_pan_joint" type="revolute">
    <parent link="rightarm_shoulder_link"/>
    <child link="rightarm_upper_arm_link"/>
    <origin rpy="0 0 0" xyz="0 0 0.126"/>
    <axis xyz="0 0 -1"/>
    <limit effort="1000" lower="0" upper="3.141592653589793" velocity="15"/>
    <dynamics damping="0"/>
  </joint>
  <!-- link 2 -->
  <link name="rightarm_upper_arm_link">
    <collision>
      <origin rpy="0 0 3.141592653589793" xyz="0 0 0.03"/>
      <geometry>
        <box size="0.06 0.14 0.06"/>
      </geometry>
    </collision>
    <visual>
      <origin rpy="0 0 3.141592653589793" xyz="0 0 -0.126"/>
      <geometry>
        <mesh filename="file:///home/thibaut/Documents/Bimanual_Robot/bimanual_ws/install/bimanualrobot_description/share/bimanualrobot_description/meshes/visual/link_2.stl" scale="0.001 0.001 0.001"/>
      </geometry>
      <material name="grey"/>
    </visual>
    <inertial>
      <!-- <origin xyz="0 0 0" rpy="0 0 0"/> -->
      <!-- <mass value="1.030"/> -->
      <!-- <inertia ixx="1.0" ixy="0.0" ixz="0.0" iyy="1.0" iyz="0.0" izz="1.0" /> -->
      <origin rpy="0 0 0" xyz="0.00000 0.00080 0.03183"/>
      <mass value="0.94658"/>
      <!-- <inertia ixx="0.00152547" ixy="0.0" ixz="0.0" iyy="0.00045954" iyz="-0.00001086" izz="0.00151740" /> -->
      <inertia ixx="0.00183005466667" ixy="0.0" ixz="0.0" iyy="0.000567948" iyz="0.0" izz="0.00183005466667"/>
    </inertial>
  </link>
  <!-- Joint 2 -->
  <joint name="rightarm_shoulder_lift_joint" type="revolute">
    <parent link="rightarm_upper_arm_link"/>
    <child link="rightarm_forearm_link"/>
    <origin rpy="0 0 0" xyz="0 0 0.033"/>
    <axis xyz="0 1 0"/>
    <limit effort="1000" lower="-1.7803405567893358" upper="1.7803405567893358" velocity="15"/>
    <dynamics damping="0"/>
  </joint>
  <!-- link 3 -->
  <link name="rightarm_forearm_link">
    <collision>
      <origin rpy="1.5707963267948966 0 3.141592653589793" xyz="-.001 0 0.148"/>
      <geometry>
        <mesh filename="file:///home/thibaut/Documents/Bimanual_Robot/bimanual_ws/install/bimanualrobot_description/share/bimanualrobot_description/meshes/collision/link3.stl"/>
      </geometry>
    </collision>
    <visual>
      <origin rpy="0 0 3.141592653589793" xyz="0 0 -0.159"/>
      <geometry>
        <mesh filename="file:///home/thibaut/Documents/Bimanual_Robot/bimanual_ws/install/bimanualrobot_description/share/bimanualrobot_description/meshes/visual/link_3.stl" scale="0.001 0.001 0.001"/>
      </geometry>
      <material name="grey"/>
    </visual>
    <inertial>
      <origin rpy="0 0 0" xyz="0 0 0.148"/>
      <!-- <mass value="1.404"/> -->
      <!-- <inertia ixx="1.0" ixy="0.0" ixz="0.0" iyy="1.0" iyz="0.0" izz="1.0" /> -->
      <mass value="1.30260"/>
      <!-- <inertia ixx="0.01111021" ixy="0.00001331" ixz="-0.00134208" iyy="0.01046642" iyz="0.00016235" izz="0.00202081" /> -->
      <inertia ixx="0.0136625102365" ixy="0.0" ixz="0.0" iyy="0.0124082569044" iyz="0.0" izz="0.00324753226791"/>
    </inertial>
  </link>
  <!-- Joint 3 -->
  <joint name="rightarm_elbow_joint" type="revolute">
    <parent link="rightarm_forearm_link"/>
    <child link="rightarm_wrist_1_link"/>
    <origin rpy="0 0.7853981633974483 0" xyz="0.03 0.0 0.264"/>
    <axis xyz="0 1 0"/>
    <limit effort="1000" lower="-1.2566370614359172" upper="2.261946710584651" velocity="15"/>
    <dynamics damping="0"/>
  </joint>
  <!-- link 4 -->
  <link name="rightarm_wrist_1_link">
    <collision>
      <origin rpy="1.5707963267948966 0 3.141592653589793" xyz="-0.03 0.0 0.1285"/>
      <geometry>
        <mesh filename="file:///home/thibaut/Documents/Bimanual_Robot/bimanual_ws/install/bimanualrobot_description/share/bimanualrobot_description/meshes/collision/link4.stl"/>
      </geometry>
    </collision>
    <visual>
      <origin rpy="0 0 3.141592653589793" xyz="-0.03 0 -0.423"/>
      <geometry>
        <mesh filename="file:///home/thibaut/Documents/Bimanual_Robot/bimanual_ws/install/bimanualrobot_description/share/bimanualrobot_description/meshes/visual/link_4.stl" scale="0.001 0.001 0.001"/>
      </geometry>
      <material name="grey"/>
    </visual>
    <inertial>
      <origin rpy="0 1.5707963267948966 0" xyz="-0.03 0 0.1285"/>
      <!-- <mass value="1.236" /> -->
      <!-- <inertia ixx="1.0" ixy="0.0" ixz="0.0" iyy="1.0" iyz="0.0" izz="1.0" /> -->
      <mass value="1.15977"/>
      <!-- <inertia ixx="0.00096726" ixy="0.00004383" ixz="-0.00002771" iyy="0.00318801" iyz="0.00000627" izz="0.00341484" /> -->
      <inertia ixx="0.00205032491251" ixy="0.0" ixz="0.0" iyy="0.00691847164616" iyz="0.0" izz="0.00765159473365"/>
    </inertial>
  </link>
  <!-- Joint 4 -->
  <joint name="rightarm_wrist_1_joint" type="revolute">
    <parent link="rightarm_wrist_1_link"/>
    <child link="rightarm_wrist_2_link"/>
    <origin rpy="0 0 0" xyz="-0.03 0.0 0.231"/>
    <axis xyz="0 0 1"/>
    <limit effort="1000" lower="-3.141592653589793" upper="3.141592653589793" velocity="15"/>
    <dynamics damping="0"/>
  </joint>
  <!-- link 5 -->
  <link name="rightarm_wrist_2_link">
    <collision>
      <origin rpy="0 0 3.141592653589793" xyz="0.0 0.0 0.024"/>
      <geometry>
        <box size="0.048 0.09 0.048"/>
      </geometry>
    </collision>
    <visual>
      <origin rpy="0 0 3.141592653589793" xyz="0 0 -0.654"/>
      <geometry>
        <mesh filename="file:///home/thibaut/Documents/Bimanual_Robot/bimanual_ws/install/bimanualrobot_description/share/bimanualrobot_description/meshes/visual/link_5.stl" scale="0.001 0.001 0.001"/>
      </geometry>
      <material name="grey"/>
    </visual>
    <inertial>
      <origin rpy="0 0 0" xyz="0 0 0.024"/>
      <!-- <mass value="0.491" /> -->
      <!-- <inertia ixx="1.0" ixy="0.0" ixz="0.0" iyy="1.0" iyz="0.0" izz="1.0" /> -->
      <mass value="0.44688"/>
      <!-- <inertia ixx="0.00030285" ixy="0.00000761" ixz="0.00000031" iyy="0.00022339" iyz="-0.00000001" izz="0.00039766" /> -->
      <inertia ixx="0.00038744496" ixy="0.0" ixz="0.0" iyy="0.00017160192" iyz="0.0" izz="0.00038744496"/>
    </inertial>
  </link>
  <!-- Joint 5 -->
  <joint name="rightarm_wrist_2_joint" type="revolute">
    <parent link="rightarm_wrist_2_link"/>
    <child link="rightarm_wrist_3_link"/>
    <origin rpy="0 0 0" xyz="0.0 0.0 0.027"/>
    <axis xyz="0 1 0"/>
    <limit effort="1000" lower="-1.5707963267948966" upper="1.5707963267948966" velocity="15"/>
    <dynamics damping="0"/>
  </joint>
  <!-- link 6 -->
  <link name="rightarm_wrist_3_link">
    <collision>
      <origin rpy="1.5707963267948966 0 1.5707963267948966" xyz="0.0 0.0 0.081"/>
      <geometry>
        <mesh filename="file:///home/thibaut/Documents/Bimanual_Robot/bimanual_ws/install/bimanualrobot_description/share/bimanualrobot_description/meshes/collision/link6.stl"/>
      </geometry>
    </collision>
    <visual>
      <origin rpy="0 0 3.141592653589793" xyz="0 0 -0.681"/>
      <geometry>
        <mesh filename="file:///home/thibaut/Documents/Bimanual_Robot/bimanual_ws/install/bimanualrobot_description/share/bimanualrobot_description/meshes/visual/link_6.stl" scale="0.001 0.001 0.001"/>
      </geometry>
      <material name="grey"/>
    </visual>
    <inertial>
      <origin rpy="1.5707963267948966 1.5707963267948966 0" xyz="0 0 0.081"/>
      <!-- <mass value="0.454" /> -->
      <!-- <inertia ixx="1.0" ixy="0.0" ixz="0.0" iyy="1.0" iyz="0.0" izz="1.0" /> -->
      <mass value="0.43273"/>
      <!-- <inertia ixx="0.00021512" ixy="0.00001009" ixz="0.00000000" iyy="0.00042827" iyz="0.00000000" izz="0.00051436" /> -->
      <inertia ixx="0.00039594795" ixy="0.0" ixz="0.0" iyy="0.00104401581334" iyz="0.0" izz="0.000775290483338"/>
    </inertial>
  </link>
  <!-- Joint 6 -->
  <joint name="rightarm_wrist_3_joint" type="revolute">
    <parent link="rightarm_wrist_3_link"/>
    <child link="rightarm_ee_link"/>
    <origin rpy="0 0 0" xyz="0.0 0.0 0.123"/>
    <axis xyz="0 0 1"/>
    <limit effort="1000" lower="-3.141592653589793" upper="3.141592653589793" velocity="15"/>
    <dynamics damping="0"/>
  </joint>
  <!-- End Effector -->
  <link name="rightarm_ee_link">
    <collision>
      <origin rpy="0 0 0" xyz="0.0 0.0 0.0"/>
      <geometry>
        <box size="0.0 0.0 0.0"/>
      </geometry>
    </collision>
    <visual>
      <origin rpy="0 0 0" xyz="0.0 0.0 0.0"/>
      <geometry>
        <box size="0.0 0.0 0.0"/>
      </geometry>
      <material name="red"/>
    </visual>
    <inertial>
      <origin rpy="0 0 0" xyz="0 0 0"/>
      <mass value="0.01"/>
      <inertia ixx="0.0000416666666667" ixy="0.0" ixz="0.0" iyy="0.0000416666666667" iyz="0.0" izz="0.0000416666666667"/>
    </inertial>
  </link>
  <!-- <xacro:manipulator_arm_transmission prefix="${prefix_val}" /> -->
  <!-- Merge all joints together -->
  <link name="world"/>
  <!-- <joint name="left_base_to_base_link" type="fixed">
    <parent link="base_link" />
    <child link = "left_base" />
    <origin xyz="0 0 0" rpy="0 0 0" />
  </joint>

  <joint name="right_base_to_base_link" type="fixed">
    <parent link="base_link" />
    <child link = "right_base" />
    <origin xyz="0 0 0" rpy="0 0 0" />
  </joint> -->
  <joint name="world_stand" type="fixed">
    <parent link="world"/>
    <child link="base_link"/>
    <origin rpy="0 0 0" xyz="0 0 0"/>
  </joint>
  <ros2_control name="leftarm_system" type="system">
    <hardware>
      <plugin>dynamixel_hardware_interface/DynamixelHardware</plugin>
      <param name="number_of_joints">6</param>
      <param name="number_of_transmissions">6</param>
      <!-- Single-port per plugin instance -->
      <param name="port_name">/dev/ttyUSB0</param>
      <param name="baud_rate">1000000</param>
      <!-- Required by the plugin (path is resolved relative to package share) -->
      <param name="dynamixel_model_folder">/param/dxl_model</param>
      <!-- Optional behavior/safety -->
      <param name="disable_torque_at_init">True</param>
      <param name="error_timeout_ms">500</param>
      <!-- Required matrices (CSV row-major) -->
      <param name="transmission_to_joint_matrix">-1,0,0,0,0,0,                 0,1,0,0,0,0,                 0,0,1,0,0,0,                 0,0,0,1,0,0,                 0,0,0,0,1,0,                 0,0,0,0,0,1</param>
      <param name="joint_to_transmission_matrix">-1,0,0,0,0,0,                 0,1,0,0,0,0,                 0,0,1,0,0,0,                 0,0,0,1,0,0,                 0,0,0,0,1,0,                 0,0,0,0,0,1</param>
    </hardware>
    <!-- Joints for this arm: position command + position/velocity states -->
    <joint name="leftarm_shoulder_pan_joint">
      <command_interface name="position"/>
      <command_interface name="effort"/>
      <state_interface name="position"/>
      <state_interface name="velocity"/>
      <state_interface name="effort"/>
    </joint>
    <joint name="leftarm_shoulder_lift_joint">
      <command_interface name="position"/>
      <command_interface name="effort"/>
      <state_interface name="position"/>
      <state_interface name="velocity"/>
      <state_interface name="effort"/>
    </joint>
    <joint name="leftarm_elbow_joint">
      <command_interface name="position"/>
      <command_interface name="effort"/>
      <state_interface name="position"/>
      <state_interface name="velocity"/>
      <state_interface name="effort"/>
    </joint>
    <joint name="leftarm_wrist_1_joint">
      <command_interface name="position"/>
      <command_interface name="effort"/>
      <state_interface name="position"/>
      <state_interface name="velocity"/>
      <state_interface name="effort"/>
    </joint>
    <joint name="leftarm_wrist_2_joint">
      <command_interface name="position"/>
      <command_interface name="effort"/>
      <state_interface name="position"/>
      <state_interface name="velocity"/>
      <state_interface name="effort"/>
    </joint>
    <joint name="leftarm_wrist_3_joint">
      <command_interface name="position"/>
      <command_interface name="effort"/>
      <state_interface name="position"/>
      <state_interface name="velocity"/>
      <state_interface name="effort"/>
    </joint>
    <!-- One GPIO “DXL” per transmission/ID with basic interfaces -->
    <gpio name="leftarm_shoulder_pan_joint_dxl">
      <param name="ID">1</param>
      <param name="type">dxl</param>
      <state_interface name="Present Position"/>
      <state_interface name="Present Velocity"/>
      <state_interface name="Hardware Error Status"/>
      <!-- <state_interface name="Error Code"/> -->
      <command_interface name="Goal Position"/>
      <command_interface name="Goal Velocity"/>
      <!-- <command_interface name="Goal Current"/> -->
      <param name="Torque Enable">1</param>
      <param name="Operating Mode">3</param>
      <param name="Position P Gain">32</param>
      <param name="Return Delay Time">0</param>
    </gpio>
    <gpio name="leftarm_shoulder_lift_joint_dxl">
      <param name="ID">2</param>
      <param name="type">dxl</param>
      <state_interface name="Present Position"/>
      <state_interface name="Present Velocity"/>
      <state_interface name="Hardware Error Status"/>
      <!-- <state_interface name="Error Code"/> -->
      <command_interface name="Goal Position"/>
      <command_interface name="Goal Velocity"/>
      <!-- <command_interface name="Goal Current"/> -->
      <param name="Torque Enable">1</param>
      <param name="Operating Mode">3</param>
      <param name="Position P Gain">32</param>
      <param name="Return Delay Time">0</param>
    </gpio>
    <gpio name="leftarm_elbow_joint_dxl">
      <param name="ID">3</param>
      <param name="type">dxl</param>
      <state_interface name="Present Position"/>
      <state_interface name="Present Velocity"/>
      <state_interface name="Hardware Error Status"/>
      <!-- <state_interface name="Error Code"/> -->
      <command_interface name="Goal Position"/>
      <command_interface name="Goal Velocity"/>
      <!-- <command_interface name="Goal Current"/> -->
      <param name="Torque Enable">1</param>
      <param name="Operating Mode">3</param>
      <param name="Position P Gain">32</param>
      <param name="Return Delay Time">0</param>
    </gpio>
    <gpio name="leftarm_wrist_1_joint_dxl">
      <param name="ID">4</param>
      <param name="type">dxl</param>
      <state_interface name="Present Position"/>
      <state_interface name="Present Velocity"/>
      <state_interface name="Hardware Error Status"/>
      <!-- <state_interface name="Error Code"/> -->
      <command_interface name="Goal Position"/>
      <command_interface name="Goal Velocity"/>
      <!-- <command_interface name="Goal Current"/> -->
      <param name="Torque Enable">1</param>
      <param name="Operating Mode">3</param>
      <param name="Position P Gain">32</param>
      <param name="Return Delay Time">0</param>
    </gpio>
    <gpio name="leftarm_wrist_2_joint_dxl">
      <param name="ID">5</param>
      <param name="type">dxl</param>
      <state_interface name="Present Position"/>
      <state_interface name="Present Velocity"/>
      <state_interface name="Hardware Error Status"/>
      <!-- <state_interface name="Error Code"/> -->
      <command_interface name="Goal Position"/>
      <command_interface name="Goal Velocity"/>
      <!-- <command_interface name="Goal Current"/> -->
      <param name="Torque Enable">1</param>
      <param name="Operating Mode">3</param>
      <param name="Position P Gain">32</param>
      <param name="Return Delay Time">0</param>
    </gpio>
    <gpio name="leftarm_wrist_3_joint_dxl">
      <param name="ID">6</param>
      <param name="type">dxl</param>
      <state_interface name="Present Position"/>
      <state_interface name="Present Velocity"/>
      <state_interface name="Hardware Error Status"/>
      <!-- <state_interface name="Error Code"/> -->
      <command_interface name="Goal Position"/>
      <command_interface name="Goal Velocity"/>
      <!-- <command_interface name="Goal Current"/> -->
      <param name="Torque Enable">1</param>
      <param name="Operating Mode">3</param>
      <param name="Position P Gain">32</param>
      <param name="Return Delay Time">0</param>
    </gpio>
  </ros2_control>
  <ros2_control name="rightarm_system" type="system">
    <hardware>
      <plugin>dynamixel_hardware_interface/DynamixelHardware</plugin>
      <param name="number_of_joints">6</param>
      <param name="number_of_transmissions">6</param>
      <!-- Single-port per plugin instance -->
      <param name="port_name">/dev/ttyUSB1</param>
      <param name="baud_rate">1000000</param>
      <!-- Required by the plugin (path is resolved relative to package share) -->
      <param name="dynamixel_model_folder">/param/dxl_model</param>
      <!-- Optional behavior/safety -->
      <param name="disable_torque_at_init">True</param>
      <param name="error_timeout_ms">500</param>
      <!-- Required matrices (CSV row-major) -->
      <param name="transmission_to_joint_matrix">-1,0,0,0,0,0,                 0,1,0,0,0,0,                 0,0,1,0,0,0,                 0,0,0,1,0,0,                 0,0,0,0,1,0,                 0,0,0,0,0,1</param>
      <param name="joint_to_transmission_matrix">-1,0,0,0,0,0,                 0,1,0,0,0,0,                 0,0,1,0,0,0,                 0,0,0,1,0,0,                 0,0,0,0,1,0,                 0,0,0,0,0,1</param>
    </hardware>
    <!-- Joints for this arm: position command + position/velocity states -->
    <joint name="rightarm_shoulder_pan_joint">
      <command_interface name="position"/>
      <state_interface name="position"/>
      <state_interface name="velocity"/>
      <state_interface name="effort"/>
    </joint>
    <joint name="rightarm_shoulder_lift_joint">
      <command_interface name="position"/>
      <state_interface name="position"/>
      <state_interface name="velocity"/>
      <state_interface name="effort"/>
    </joint>
    <joint name="rightarm_elbow_joint">
      <command_interface name="position"/>
      <state_interface name="position"/>
      <state_interface name="velocity"/>
      <state_interface name="effort"/>
    </joint>
    <joint name="rightarm_wrist_1_joint">
      <command_interface name="position"/>
      <state_interface name="position"/>
      <state_interface name="velocity"/>
      <state_interface name="effort"/>
    </joint>
    <joint name="rightarm_wrist_2_joint">
      <command_interface name="position"/>
      <state_interface name="position"/>
      <state_interface name="velocity"/>
      <state_interface name="effort"/>
    </joint>
    <joint name="rightarm_wrist_3_joint">
      <command_interface name="position"/>
      <state_interface name="position"/>
      <state_interface name="velocity"/>
      <state_interface name="effort"/>
    </joint>
    <!-- One GPIO “DXL” per transmission/ID with basic interfaces -->
    <gpio name="rightarm_shoulder_pan_joint_dxl">
      <param name="ID">1</param>
      <param name="type">dxl</param>
      <state_interface name="Present Position"/>
      <state_interface name="Present Velocity"/>
      <state_interface name="Hardware Error Status"/>
      <!-- <state_interface name="Error Code"/> -->
      <command_interface name="Goal Position"/>
      <command_interface name="Goal Velocity"/>
      <!-- <command_interface name="Goal Current"/> -->
      <param name="Torque Enable">1</param>
      <param name="Operating Mode">3</param>
      <param name="Position P Gain">32</param>
      <param name="Return Delay Time">0</param>
    </gpio>
    <gpio name="rightarm_shoulder_lift_joint_dxl">
      <param name="ID">2</param>
      <param name="type">dxl</param>
      <state_interface name="Present Position"/>
      <state_interface name="Present Velocity"/>
      <state_interface name="Hardware Error Status"/>
      <!-- <state_interface name="Error Code"/> -->
      <command_interface name="Goal Position"/>
      <command_interface name="Goal Velocity"/>
      <!-- <command_interface name="Goal Current"/> -->
      <param name="Torque Enable">1</param>
      <param name="Operating Mode">3</param>
      <param name="Position P Gain">32</param>
      <param name="Return Delay Time">0</param>
    </gpio>
    <gpio name="rightarm_elbow_joint_dxl">
      <param name="ID">3</param>
      <param name="type">dxl</param>
      <state_interface name="Present Position"/>
      <state_interface name="Present Velocity"/>
      <state_interface name="Hardware Error Status"/>
      <!-- <state_interface name="Error Code"/> -->
      <command_interface name="Goal Position"/>
      <command_interface name="Goal Velocity"/>
      <!-- <command_interface name="Goal Current"/> -->
      <param name="Torque Enable">1</param>
      <param name="Operating Mode">3</param>
      <param name="Position P Gain">32</param>
      <param name="Return Delay Time">0</param>
    </gpio>
    <gpio name="rightarm_wrist_1_joint_dxl">
      <param name="ID">4</param>
      <param name="type">dxl</param>
      <state_interface name="Present Position"/>
      <state_interface name="Present Velocity"/>
      <state_interface name="Hardware Error Status"/>
      <!-- <state_interface name="Error Code"/> -->
      <command_interface name="Goal Position"/>
      <command_interface name="Goal Velocity"/>
      <!-- <command_interface name="Goal Current"/> -->
      <param name="Torque Enable">1</param>
      <param name="Operating Mode">3</param>
      <param name="Position P Gain">32</param>
      <param name="Return Delay Time">0</param>
    </gpio>
    <gpio name="rightarm_wrist_2_joint_dxl">
      <param name="ID">5</param>
      <param name="type">dxl</param>
      <state_interface name="Present Position"/>
      <state_interface name="Present Velocity"/>
      <state_interface name="Hardware Error Status"/>
      <!-- <state_interface name="Error Code"/> -->
      <command_interface name="Goal Position"/>
      <command_interface name="Goal Velocity"/>
      <!-- <command_interface name="Goal Current"/> -->
      <param name="Torque Enable">1</param>
      <param name="Operating Mode">3</param>
      <param name="Position P Gain">32</param>
      <param name="Return Delay Time">0</param>
    </gpio>
    <gpio name="rightarm_wrist_3_joint_dxl">
      <param name="ID">6</param>
      <param name="type">dxl</param>
      <state_interface name="Present Position"/>
      <state_interface name="Present Velocity"/>
      <state_interface name="Hardware Error Status"/>
      <!-- <state_interface name="Error Code"/> -->
      <command_interface name="Goal Position"/>
      <command_interface name="Goal Velocity"/>
      <!-- <command_interface name="Goal Current"/> -->
      <param name="Torque Enable">1</param>
      <param name="Operating Mode">3</param>
      <param name="Position P Gain">32</param>
      <param name="Return Delay Time">0</param>
    </gpio>
  </ros2_control>
  <!-- <xacro:bimanualrobot_ros2_control
   prefix="rightarm"
   use_gazebo="$(arg use_gazebo)"
   use_gripper="$(arg use_gripper)"
   gripper_type="$(arg gripper_type)"
   /> -->
</robot>
